#VRML_SIM R2023b utf8

EXTERNPROTO "https://raw.githubusercontent.com/cyberbotics/webots/R2023b/projects/appearances/protos/OsbWood.proto"
EXTERNPROTO "https://raw.githubusercontent.com/cyberbotics/webots/R2023b/projects/objects/floors/protos/RectangleArena.proto"
EXTERNPROTO "https://raw.githubusercontent.com/cyberbotics/webots/R2023b/projects/objects/backgrounds/protos/TexturedBackground.proto"
EXTERNPROTO "https://raw.githubusercontent.com/cyberbotics/webots/R2023b/projects/objects/backgrounds/protos/TexturedBackgroundLight.proto"

WorldInfo {
  info [
    "In this example, the robot turns on a slope."
    "Its accelerometer sensor is used to switch on the bottommost LED."
  ]
  title "Accelerometer"
  basicTimeStep 8
  contactProperties [
    ContactProperties {
      material2 "body"
      coulombFriction [
        0
      ]
      softCFM 0.1
    }
  ]
}
Viewpoint {
  orientation 0.2868643913308916 -0.7968710774065885 -0.5317003921187384 4.998829952156781
  position -0.46093228653667684 -0.6232813387409228 1.3659557785503182
}
TexturedBackground {
}
TexturedBackgroundLight {
}
RectangleArena {
}
PointLight {
  attenuation 0 0 1
  intensity 0.6
  location 0.6 0 0
}
DEF SLOPE Solid {
  translation 0 0 0.15
  rotation 1 0 0 -1.970795
  children [
    Shape {
      appearance OsbWood {
        textureTransform TextureTransform {
          scale 0.5 2
        }
      }
      geometry DEF BOX0 Box {
        size 0.2 0.02 0.8
      }
    }
  ]
  name "green box"
  boundingObject USE BOX0
}
Robot {
  translation -0.04192095368528119 0.03575659921643366 0.14583378452350057
  rotation -0.2994655379651091 -0.24803035677748178 -0.921304148307226 1.347002971206675
  children [
    LED {
      translation -0.03 -0.05 0
      children [
        Pose {
          translation 0.03 0.02 0.087
          children [
            Shape {
              appearance PBRAppearance {
                baseColor 0 0 0
                roughness 1
                metalness 0
              }
              geometry Cone {
                bottomRadius 0.01
                height 0.01
              }
            }
          ]
        }
      ]
      name "right led"
    }
    LED {
      translation -0.03 0.01 0
      children [
        Pose {
          translation 0.03 0.02 0.087
          children [
            Shape {
              appearance PBRAppearance {
                baseColor 0 0 0
                roughness 1
                metalness 0
              }
              geometry Cone {
                bottomRadius 0.01
                height 0.01
              }
            }
          ]
        }
      ]
      name "left led"
    }
    LED {
      translation -0.06 0 0.01
      children [
        Pose {
          translation 0.03 0 0.077
          children [
            Shape {
              appearance PBRAppearance {
                baseColor 0 0 0
                roughness 1
                metalness 0
              }
              geometry Cone {
                bottomRadius 0.01
                height 0.01
              }
            }
          ]
        }
      ]
      name "back led"
    }
    LED {
      children [
        Pose {
          translation 0.03 0 0.087
          children [
            Shape {
              appearance PBRAppearance {
                baseColor 0 0 0
                roughness 1
                metalness 0
              }
              geometry Cone {
                bottomRadius 0.01
                height 0.01
              }
            }
          ]
        }
      ]
      name "front led"
    }
    Accelerometer {
    }
    Pose {
      translation 0 0 0.0415
      children [
        Shape {
          appearance PBRAppearance {
            baseColor 0.0820075 0.364731 0.8
            roughness 1
            metalness 0
          }
          geometry DEF BODY Cylinder {
            height 0.08
            radius 0.045
          }
        }
      ]
    }
    HingeJoint {
      jointParameters HingeJointParameters {
        position 192.73567690585492
        axis 0 1 0
        anchor 0 0 0.025
      }
      device [
        RotationalMotor {
          name "left wheel motor"
          consumptionFactor 70
        }
        PositionSensor {
          name "left wheel sensor"
        }
      ]
      endPoint Solid {
        translation 0 0.04499999999999996 0.025
        rotation -0.6970883442726963 0.697088395398338 -0.16773672609217358 2.8092134438466014
        children [
          DEF WHEEL Pose {
            rotation 0.577656895078166 0.5771968951617173 -0.5771968951617173 -2.093935
            children [
              Shape {
                appearance PBRAppearance {
                  baseColor 1 0 0
                  roughness 1
                  metalness 0
                }
                geometry Cylinder {
                  height 0.01
                  radius 0.025
                }
              }
            ]
          }
        ]
        name "left wheel"
        boundingObject USE WHEEL
        physics DEF PHYSICS_WHEEL Physics {
          density -1
          mass 0.05
        }
        linearVelocity 1.2956711103831599e-08 5.238967357868865e-06 -2.2149584426379884e-06
        angularVelocity -2.1849235842320795e-08 -3.943785784386852e-07 -9.144755422311778e-07
      }
    }
    HingeJoint {
      jointParameters HingeJointParameters {
        position -46.82396149389756
        axis 0 1 0
        anchor 0 0 0.025
      }
      device [
        RotationalMotor {
          name "right wheel motor"
          consumptionFactor 70
        }
        PositionSensor {
          name "right wheel sensor"
        }
      ]
      endPoint Solid {
        translation 0 -0.04499999999999995 0.025
        rotation -0.6269791828932658 0.6269792472925586 -0.46237877079614004 2.2753920760319017
        children [
          USE WHEEL
        ]
        boundingObject USE WHEEL
        physics USE PHYSICS_WHEEL
        linearVelocity -1.3302616129158517e-08 5.317883455236752e-06 -2.248363772713807e-06
        angularVelocity -2.181944356112711e-08 -3.9437017814209196e-07 -9.144790845156475e-07
      }
    }
    DistanceSensor {
      translation 0.042 0.02 0.063
      rotation 0 0 -1 -0.499205
      children [
        DEF SENSOR Pose {
          rotation 0.577656895078166 0.5771968951617173 -0.5771968951617173 -2.093935
          children [
            Shape {
              appearance PBRAppearance {
                baseColor 0.975691 0.981481 0.0252992
                roughness 1
                metalness 0
              }
              geometry Cylinder {
                height 0.004
                radius 0.008
              }
            }
          ]
        }
      ]
      name "ds0"
      lookupTable [
        0 1024 0
        0.05 1024 0
        0.15 0 0
      ]
      numberOfRays 2
      aperture 1
    }
    DistanceSensor {
      translation 0.042 -0.02 0.063
      rotation 0 0 1 -0.500795
      children [
        USE SENSOR
      ]
      name "ds1"
      lookupTable [
        0 1024 0
        0.05 1024 0
        0.15 0 0
      ]
      numberOfRays 2
      aperture 1
    }
    DEF SMILE Pose {
      translation 0.0495732 0.00397074 0.025
      rotation 0 0 -0.9999999999999999 0.5007953071795863
      children [
        Shape {
          appearance PBRAppearance {
            baseColor 0.721569 0.290196 0.290196
            roughness 1
            metalness 0
          }
          geometry Cylinder {
            height 0.018
            radius 0.009
            subdivision 3
          }
        }
      ]
    }
  ]
  name "MyBot"
  contactMaterial "body"
  boundingObject Pose {
    translation 0 0 0.0415
    rotation 0 0 1 -1.570796
    children [
      USE BODY
    ]
  }
  physics Physics {
    density -1
    mass 0.5
  }
  controller "my_controller"
  linearVelocity 1.1744812334902586e-09 5.2791522968727e-06 -2.2320063545748765e-06
  angularVelocity -2.175500353948948e-08 -3.94351993953094e-07 -9.144867838319691e-07
}
